Workbook

Sheet heart
A1: age | B1: sex | C1: cp | D1: trestbps | E1: chol | F1: fbs | G1: restecg | H1: thalach | I1: exang | J1: oldpeak | K1: slope | L1: ca | M1: thal | N1: target
A2: 52 | B2: 1 | C2: 0 | D2: 125 | E2: 212 | F2: 0 | G2: 1 | H2: 168 | I2: 0 | J2: 1 | K2: 2 | L2: 2 | M2: 3 | N2: 0
A3: 53 | B3: 1 | C3: 0 | D3: 140 | E3: 203 | F3: 1 | G3: 0 | H3: 155 | I3: 1 | J3: 3.1 | K3: 0 | L3: 0 | M3: 3 | N3: 0
A4: 70 | B4: 1 | C4: 0 | D4: 145 | E4: 174 | F4: 0 | G4: 1 | H4: 125 | I4: 1 | J4: 2.6 | K4: 0 | L4: 0 | M4: 3 | N4: 0
A5: 61 | B5: 1 | C5: 0 | D5: 148 | E5: 203 | F5: 0 | G5: 1 | H5: 161 | I5: 0 | J5: 0 | K5: 2 | L5: 1 | M5: 3 | N5: 0
A6: 62 | B6: 0 | C6: 0 | D6: 138 | E6: 294 | F6: 1 | G6: 1 | H6: 106 | I6: 0 | J6: 1.9 | K6: 1 | L6: 3 | M6: 2 | N6: 0
A7: 58 | B7: 0 | C7: 0 | D7: 100 | E7: 248 | F7: 0 | G7: 0 | H7: 122 | I7: 0 | J7: 1 | K7: 1 | L7: 0 | M7: 2 | N7: 1
A8: 58 | B8: 1 | C8: 0 | D8: 114 | E8: 318 | F8: 0 | G8: 2 | H8: 140 | I8: 0 | J8: 4.4 | K8: 0 | L8: 3 | M8: 1 | N8: 0
A9: 55 | B9: 1 | C9: 0 | D9: 160 | E9: 289 | F9: 0 | G9: 0 | H9: 145 | I9: 1 | J9: 0.8 | K9: 1 | L9: 1 | M9: 3 | N9: 0
A10: 46 | B10: 1 | C10: 0 | D10: 120 | E10: 249 | F10: 0 | G10: 0 | H10: 144 | I10: 0 | J10: 0.8 | K10: 2 | L10: 0 | M10: 3 | N10: 0
A11: 54 | B11: 1 | C11: 0 | D11: 122 | E11: 286 | F11: 0 | G11: 0 | H11: 116 | I11: 1 | J11: 3.2 | K11: 1 | L11: 2 | M11: 2 | N11: 0
A12: 71 | B12: 0 | C12: 0 | D12: 112 | E12: 149 | F12: 0 | G12: 1 | H12: 125 | I12: 0 | J12: 1.6 | K12: 1 | L12: 0 | M12: 2 | N12: 1
A13: 43 | B13: 0 | C13: 0 | D13: 132 | E13: 341 | F13: 1 | G13: 0 | H13: 136 | I13: 1 | J13: 3 | K13: 1 | L13: 0 | M13: 3 | N13: 0
... A303: 54 | B303: 1 | C303: 0 | D303: 120 | E303: 188 | F303: 0 | G303: 1 | H303: 113 | I303: 0 | J303: 1.4 | K303: 1 | L303: 1 | M303: 3 | N303: 0

Sheet tabel fitur
A1: Nama Fitur | B1: Tipe Data | C1: Deskripsi
A2: age | B2: Numerik | C2: Usia pasien dalam tahun
A3: sex | B3: Numerik (0/1) | C3: Jenis kelamin (0 = wanita, 1 = pria)
A4: cp | B4: Numerik (0–3) | C4: Jenis nyeri dada (4 kategori)
A5: trestbps | B5: Numerik | C5: Resting blood pressure (mmHg)
A6: chol | B6: Numerik | C6: Serum cholesterol (mg/dl)
A7: fbs | B7: Numerik (0/1) | C7: Fasting blood sugar > 120 mg/dl
A8: restecg | B8: Numerik (0–2) | C8: Hasil pemeriksaan elektrokardiografi
A9: thalach | B9: Numerik | C9: Detak jantung maksimum yang dicapai
A10: exang | B10: Numerik (0/1) | C10: Angina akibat olahraga
A11: oldpeak | B11: Numerik | C11: ST depression yang diinduksi oleh latihan
A12: slope | B12: Numerik (0–2) | C12: Kemiringan segmen ST
... A15: target | B15: Numerik (0/1) | C15: 1 = penyakit jantung, 0 = normal

Sheet tabel 2.1
A1: Variabel | B1: Mean | C1: Std Dev | D1: Min | E1: Max
A2: age | B2: =AVERAGE(heart!A$2:A$303) -> 54.42053 | C2: =_xlfn.STDEV.S(heart!A$2:A$303) -> 9.0479697 | D2: =MIN(heart!A$2:A$303) -> 29 | E2: =MAX(heart!A$2:A$303) -> 77
A3: sex | B3: =AVERAGE(heart!B$2:B$303) -> 0.68211921 | C3: =_xlfn.STDEV.S(heart!B$2:B$303) -> 0.46642574 | D3: =MIN(heart!B$2:B$303) -> 0 | E3: =MAX(heart!B$2:B$303) -> 1
A4: cp | B4: =AVERAGE(heart!C$2:C$303) -> 0.96357616 | C4: =_xlfn.STDEV.S(heart!C$2:C$303) -> 1.0320436 | D4: =MIN(heart!C$2:C$303) -> 0 | E4: =MAX(heart!C$2:C$303) -> 3
A5: trestbps | B5: =AVERAGE(heart!D$2:D$303) -> 131.60265 | C5: =_xlfn.STDEV.S(heart!D$2:D$303) -> 17.563394 | D5: =MIN(heart!D$2:D$303) -> 94 | E5: =MAX(heart!D$2:D$303) -> 200
A6: chol | B6: =AVERAGE(heart!E$2:E$303) -> 246.5 | C6: =_xlfn.STDEV.S(heart!E$2:E$303) -> 51.753489 | D6: =MIN(heart!E$2:E$303) -> 126 | E6: =MAX(heart!E$2:E$303) -> 564
A7: fbs | B7: =AVERAGE(heart!F$2:F$303) -> 0.14900662 | C7: =_xlfn.STDEV.S(heart!F$2:F$303) -> 0.35668603 | D7: =MIN(heart!F$2:F$303) -> 0 | E7: =MAX(heart!F$2:F$303) -> 1
A8: restecg | B8: =AVERAGE(heart!G$2:G$303) -> 0.52649007 | C8: =_xlfn.STDEV.S(heart!G$2:G$303) -> 0.52602717 | D8: =MIN(heart!G$2:G$303) -> 0 | E8: =MAX(heart!G$2:G$303) -> 2
A9: thalach | B9: =AVERAGE(heart!H$2:H$303) -> 149.56954 | C9: =_xlfn.STDEV.S(heart!H$2:H$303) -> 22.903527 | D9: =MIN(heart!H$2:H$303) -> 71 | E9: =MAX(heart!H$2:H$303) -> 202
A10: exang | B10: =AVERAGE(heart!I$2:I$303) -> 0.32781457 | C10: =_xlfn.STDEV.S(heart!I$2:I$303) -> 0.47019596 | D10: =MIN(heart!I$2:I$303) -> 0 | E10: =MAX(heart!I$2:I$303) -> 1
A11: oldpeak | B11: =AVERAGE(heart!J$2:J$303) -> 1.0430464 | C11: =_xlfn.STDEV.S(heart!J$2:J$303) -> 1.1614523 | D11: =MIN(heart!J$2:J$303) -> 0 | E11: =MAX(heart!J$2:J$303) -> 6.2
A12: slope | B12: =AVERAGE(heart!K$2:K$303) -> 1.397351 | C12: =_xlfn.STDEV.S(heart!K$2:K$303) -> 0.61627398 | D12: =MIN(heart!K$2:K$303) -> 0 | E12: =MAX(heart!K$2:K$303) -> 2
A13: ca | B13: =AVERAGE(heart!L$2:L$303) -> 0.71854305 | C13: =_xlfn.STDEV.S(heart!L$2:L$303) -> 1.0067483 | D13: =MIN(heart!L$2:L$303) -> 0 | E13: =MAX(heart!L$2:L$303) -> 4
A14: thal | B14: =AVERAGE(heart!M$2:M$303) -> 2.3145695 | C14: =_xlfn.STDEV.S(heart!M$2:M$303) -> 0.61302554 | D14: =MIN(heart!M$2:M$303) -> 0 | E14: =MAX(heart!M$2:M$303) -> 3
A15: target | B15: =AVERAGE(heart!N$2:N$303) -> 0.54304636 | C15: =_xlfn.STDEV.S(heart!N$2:N$303) -> 0.49897036 | D15: =MIN(heart!N$2:N$303) -> 0 | E15: =MAX(heart!N$2:N$303) -> 1

Sheet tabel 2.2
A1: Kelas (target) | B1: Keterangan | C1: Jumlah
A2: 0 | B2: Tidak memiliki penyakit jantung | C2: =COUNTIF(heart!N2:N303,0) -> 138
A3: 1 | B3: Memiliki penyakit jantung | C3: =COUNTIF(heart!N2:N303,1) -> 164
A4: Total | B4: Jumlah Data | C4: =SUM(C2:C3) -> 302

Sheet histogram
A1: Bin Upper | C1: Label | E1: Hitung BIN WIDTH Age Dengan Freedman–Diaconis
A2: =F7 -> 29 | B2: =COUNTIFS(heart!$A$2:$A$303,">="&A2, heart!$A$2:$A$303,"<"&A3) -> 1 | C2: =A2 & "–" & A3-1 -> 29–32
A3: =A2+$F$6 -> 33 | B3: =COUNTIFS(heart!$A$2:$A$303,">="&A3, heart!$A$2:$A$303,"<"&A4) -> 6 | C3: =A3 & "–" & A4-1 -> 33–36 | E3: Q1 | F3: =_xlfn.QUARTILE.INC(heart!A2:A303,1) -> 48
A4: =A3+$F$6 -> 37 | B4: =COUNTIFS(heart!$A$2:$A$303,">="&A4, heart!$A$2:$A$303,"<"&A5) -> 11 | C4: =A4 & "–" & A5-1 -> 37–40 | E4: Q3 | F4: =_xlfn.QUARTILE.INC(heart!A2:A303,3) -> 61
A5: =A4+$F$6 -> 41 | B5: =COUNTIFS(heart!$A$2:$A$303,">="&A5, heart!$A$2:$A$303,"<"&A6) -> 37 | C5: =A5 & "–" & A6-1 -> 41–44 | E5: IQR | F5: =F4-F3 -> 13
A6: =A5+$F$6 -> 45 | B6: =COUNTIFS(heart!$A$2:$A$303,">="&A6, heart!$A$2:$A$303,"<"&A7) -> 27 | C6: =A6 & "–" & A7-1 -> 45–48 | E6: bin width | F6: =MROUND(2*F5/(COUNT(heart!A2:A303)^(1/3)),1) -> 4
A7: =A6+$F$6 -> 49 | B7: =COUNTIFS(heart!$A$2:$A$303,">="&A7, heart!$A$2:$A$303,"<"&A8) -> 37 | C7: =A7 & "–" & A8-1 -> 49–52 | E7: min age | F7: ='tabel 2.1'!D2 -> 29
A8: =A7+$F$6 -> 53 | B8: =COUNTIFS(heart!$A$2:$A$303,">="&A8, heart!$A$2:$A$303,"<"&A9) -> 43 | C8: =A8 & "–" & A9-1 -> 53–56 | E8: max age | F8: ='tabel 2.1'!E2 -> 77
A9: =A8+$F$6 -> 57 | B9: =COUNTIFS(heart!$A$2:$A$303,">="&A9, heart!$A$2:$A$303,"<"&A10) -> 61 | C9: =A9 & "–" & A10-1 -> 57–60
A10: =A9+$F$6 -> 61 | B10: =COUNTIFS(heart!$A$2:$A$303,">="&A10, heart!$A$2:$A$303,"<"&A11) -> 38 | C10: =A10 & "–" & A11-1 -> 61–64
A11: =A10+$F$6 -> 65 | B11: =COUNTIFS(heart!$A$2:$A$303,">="&A11, heart!$A$2:$A$303,"<"&A12) -> 28 | C11: =A11 & "–" & A12-1 -> 65–68
A12: =A11+$F$6 -> 69 | B12: =COUNTIFS(heart!$A$2:$A$303,">="&A12, heart!$A$2:$A$303,"<"&A13) -> 10 | C12: =A12 & "–" & A13-1 -> 69–72
A13: =A12+$F$6 -> 73 | B13: =COUNTIFS(heart!$A$2:$A$303,">="&A13, heart!$A$2:$A$303,"<"&A14) -> 2 | C13: =A13 & "–" & A14-1 -> 73–76
A14: =A13+$F$6 -> 77 | B14: =COUNTIFS(heart!$A$2:$A$303,">="&A14, heart!$A$2:$A$303,"<"&A15) -> 0 | C14: =A14 -> 77
A23: Bin Upper | C23: Label | E23: Hitung BIN WIDTH Trestbps Dengan Freedman–Diaconis
A24: =F29 -> 94 | B24: =COUNTIFS(heart!$D$2:$D$303,">="&A24, heart!$D$2:$D$303,"<"&A25) -> 2 | C24: =A24 & "–" & A25-1 -> 94–99
A25: =A24+$F$28 -> 100 | B25: =COUNTIFS(heart!$D$2:$D$303,">="&A25, heart!$D$2:$D$303,"<"&A26) -> 11 | C25: =A25 & "–" & A26-1 -> 100–105 | E25: Q1 | F25: =_xlfn.QUARTILE.INC(heart!D2:D303,1) -> 120
A26: =A25+$F$28 -> 106 | B26: =COUNTIFS(heart!$D$2:$D$303,">="&A26, heart!$D$2:$D$303,"<"&A27) -> 26 | C26: =A26 & "–" & A27-1 -> 106–111 | E26: Q3 | F26: =_xlfn.QUARTILE.INC(heart!D2:D303,3) -> 140
A27: =A26+$F$28 -> 112 | B27: =COUNTIFS(heart!$D$2:$D$303,">="&A27, heart!$D$2:$D$303,"<"&A28) -> 14 | C27: =A27 & "–" & A28-1 -> 112–117 | E27: IQR | F27: =F26-F25 -> 20
A28: =A27+$F$28 -> 118 | B28: =COUNTIFS(heart!$D$2:$D$303,">="&A28, heart!$D$2:$D$303,"<"&A29) -> 49 | C28: =A28 & "–" & A29-1 -> 118–123 | E28: bin width | F28: =MROUND(2*F27/(COUNT(heart!D2:D303)^(1/3)),1) -> 6
A29: =A28+$F$28 -> 124 | B29: =COUNTIFS(heart!$D$2:$D$303,">="&A29, heart!$D$2:$D$303,"<"&A30) -> 33 | C29: =A29 & "–" & A30-1 -> 124–129 | E29: min trestbps | F29: ='tabel 2.1'!D5 -> 94
A30: =A29+$F$28 -> 130 | B30: =COUNTIFS(heart!$D$2:$D$303,">="&A30, heart!$D$2:$D$303,"<"&A31) -> 55 | C30: =A30 & "–" & A31-1 -> 130–135 | E30: max trestbps | F30: ='tabel 2.1'!E5 -> 200
A31: =A30+$F$28 -> 136 | B31: =COUNTIFS(heart!$D$2:$D$303,">="&A31, heart!$D$2:$D$303,"<"&A32) -> 47 | C31: =A31 & "–" & A32-1 -> 136–141
A32: =A31+$F$28 -> 142 | B32: =COUNTIFS(heart!$D$2:$D$303,">="&A32, heart!$D$2:$D$303,"<"&A33) -> 12 | C32: =A32 & "–" & A33-1 -> 142–147
A33: =A32+$F$28 -> 148 | B33: =COUNTIFS(heart!$D$2:$D$303,">="&A33, heart!$D$2:$D$303,"<"&A34) -> 24 | C33: =A33 & "–" & A34-1 -> 148–153
A34: =A33+$F$28 -> 154 | B34: =COUNTIFS(heart!$D$2:$D$303,">="&A34, heart!$D$2:$D$303,"<"&A35) -> 3 | C34: =A34 & "–" & A35-1 -> 154–159
A35: =A34+$F$28 -> 160 | B35: =COUNTIFS(heart!$D$2:$D$303,">="&A35, heart!$D$2:$D$303,"<"&A36) -> 13 | C35: =A35 & "–" & A36-1 -> 160–165
A36: =A35+$F$28 -> 166 | B36: =COUNTIFS(heart!$D$2:$D$303,">="&A36, heart!$D$2:$D$303,"<"&A37) -> 4 | C36: =A36 & "–" & A37-1 -> 166–171
A37: =A36+$F$28 -> 172 | B37: =COUNTIFS(heart!$D$2:$D$303,">="&A37, heart!$D$2:$D$303,"<"&A38) -> 2 | C37: =A37 & "–" & A38-1 -> 172–177
A38: =A37+$F$28 -> 178 | B38: =COUNTIFS(heart!$D$2:$D$303,">="&A38, heart!$D$2:$D$303,"<"&A39) -> 5 | C38: =A38 & "–" & A39-1 -> 178–183
A39: =A38+$F$28 -> 184 | B39: =COUNTIFS(heart!$D$2:$D$303,">="&A39, heart!$D$2:$D$303,"<"&A40) -> 0 | C39: =A39 & "–" & A40-1 -> 184–189
A40: =A39+$F$28 -> 190 | B40: =COUNTIFS(heart!$D$2:$D$303,">="&A40, heart!$D$2:$D$303,"<"&A41) -> 1 | C40: =A40 & "–" & A41-1 -> 190–195
A41: =A40+$F$28 -> 196 | B41: =COUNTIFS(heart!$D$2:$D$303,">="&A41, heart!$D$2:$D$303,"<"&A42) -> 1 | C41: =A41 & "–" & A42-1 -> 196–201
A42: =A41+$F$28 -> 202 | B42: =COUNTIFS(heart!$D$2:$D$303,">="&A42, heart!$D$2:$D$303,"<"&A43) -> 0 | C42: =A42 -> 202
A46: Bin Upper | C46: Label | E46: Hitung BIN WIDTH Chol Dengan Freedman–Diaconis
A47: =F52 -> 126 | B47: =COUNTIFS(heart!$E$2:$E$303,">="&A47, heart!$E$2:$E$303,"<"&A48) -> 3 | C47: =A47 & "–" & A48-1 -> 126–144
A48: =A47+$F$51 -> 145 | B48: =COUNTIFS(heart!$E$2:$E$303,">="&A48, heart!$E$2:$E$303,"<"&A49) -> 4 | C48: =A48 & "–" & A49-1 -> 145–163 | E48: Q1 | F48: =_xlfn.QUARTILE.INC(heart!E2:E303,1) -> 211
A49: =A48+$F$51 -> 164 | B49: =COUNTIFS(heart!$E$2:$E$303,">="&A49, heart!$E$2:$E$303,"<"&A50) -> 17 | C49: =A49 & "–" & A50-1 -> 164–182 | E49: Q3 | F49: =_xlfn.QUARTILE.INC(heart!E2:E303,3) -> 274.75
A50: =A49+$F$51 -> 183 | B50: =COUNTIFS(heart!$E$2:$E$303,">="&A50, heart!$E$2:$E$303,"<"&A51) -> 29 | C50: =A50 & "–" & A51-1 -> 183–201 | E50: IQR | F50: =F49-F48 -> 63.75
A51: =A50+$F$51 -> 202 | B51: =COUNTIFS(heart!$E$2:$E$303,">="&A51, heart!$E$2:$E$303,"<"&A52) -> 45 | C51: =A51 & "–" & A52-1 -> 202–220 | E51: bin width | F51: =MROUND(2*F50/(COUNT(heart!E2:E303)^(1/3)),1) -> 19
...

Sheet heatmap
B1: age | C1: trestbps | D1: chol | E1: thalach | F1: oldpeak | G1: target
A2: age | B2: 1 | C2: =CORREL(heart!A2:A303, heart!D2:D303) -> 0.28312068 | D2: =CORREL(heart!A2:A303, heart!E2:E303) -> 0.20721551 | E2: =CORREL(heart!A2:A303, heart!H2:H303) -> -0.39523519 | F2: =CORREL(heart!A2:A303, heart!J2:J303) -> 0.20603964 | G2: =CORREL(heart!A2:A303, heart!N2:N303) -> -0.22147583
A3: trestbps | B3: =CORREL(heart!D2:D303, heart!A2:A303) -> 0.28312068 | C3: 1 | D3: =CORREL(heart!D2:D303, heart!E2:E303) -> 0.12525629 | E3: =CORREL(heart!D2:D303, heart!H2:H303) -> -0.048022712 | F3: =CORREL(heart!D2:D303, heart!J2:J303) -> 0.19459995 | G3: =CORREL(heart!D2:D303, heart!N2:N303) -> -0.14626866
A4: chol | B4: =CORREL(heart!E2:E303, heart!A2:A303) -> 0.20721551 | C4: =CORREL(heart!E2:E303, heart!D2:D303) -> 0.12525629 | D4: 1 | E4: =CORREL(heart!E2:E303, heart!H2:H303) -> -0.0053084958 | F4: =CORREL(heart!E2:E303, heart!J2:J303) -> 0.050086024 | G4: =CORREL(heart!E2:E303, heart!N2:N303) -> -0.081437201
A5: thalach | B5: =CORREL(heart!H2:H303, heart!A2:A303) -> -0.39523519 | C5: =CORREL(heart!H2:H303, heart!D2:D303) -> -0.048022712 | D5: =CORREL(heart!H2:H303, heart!E2:E303) -> -0.0053084958 | E5: 1 | F5: =CORREL(heart!H2:H303, heart!J2:J303) -> -0.34220075 | G5: =CORREL(heart!H2:H303, heart!N2:N303) -> 0.41995504
A6: oldpeak | B6: =CORREL(heart!J2:J303, heart!A2:A303) -> 0.20603964 | C6: =CORREL(heart!J2:J303, heart!D2:D303) -> 0.19459995 | D6: =CORREL(heart!J2:J303, heart!E2:E303) -> 0.050086024 | E6: =CORREL(heart!J2:J303, heart!H2:H303) -> -0.34220075 | F6: 1 | G6: =CORREL(heart!J2:J303, heart!N2:N303) -> -0.42914583
A7: target | B7: =CORREL(heart!N2:N303, heart!A2:A303) -> -0.22147583 | C7: =CORREL(heart!N2:N303, heart!D2:D303) -> -0.14626866 | D7: =CORREL(heart!N2:N303, heart!E2:E303) -> -0.081437201 | E7: =CORREL(heart!N2:N303, heart!H2:H303) -> 0.41995504 | F7: =CORREL(heart!N2:N303, heart!J2:J303) -> -0.42914583 | G7: 1

Sheet boxplot
